<mujoco model="alicia_dual_arm_simple">
  <compiler angle="radian"/>
  <option timestep="0.002" gravity="0 0 -9.81"/>

  <visual>
    <scale jointwidth="0.015" framelength="0.2" framewidth="0.008"/>
  </visual>

  <asset>
    <texture builtin="gradient" height="100" rgb1=".4 .5 .6" rgb2="0 0 0" type="skybox" width="100"/>
    <texture builtin="checker" height="100" name="texplane" rgb1="1 1 1" rgb2=".8 .9 1" type="2d" width="100"/>
    <material name="MatPlane" reflectance="0.5" texrepeat="1 1" texture="texplane" texuniform="true"/>
    <material name="blue" rgba="0.3 0.3 0.8 1"/>
    <material name="red" rgba="0.8 0.3 0.3 1"/>
  </asset>

  <worldbody>
    <geom type="plane" size="2 2 0.1" material="MatPlane"/>
    <light diffuse=".5 .5 .5" pos="0 0 3" dir="0 0 -1"/>

    <!-- 左臂 (蓝色) -->
    <body name="left_base_link" pos="-0.35 0 0">
      <geom type="cylinder" size="0.05 0.03" rgba="0.3 0.3 0.8 1" pos="0 0 0.065"/>
      <body name="left_Link1" pos="0 0 0.1295">
        <inertial pos="0 0 0.003" mass="0.19" diaginertia="0.00034 0.00026 0.00015"/>
        <joint name="left_Joint1" axis="0 0 1" range="-2.16 2.16" damping="0.01"/>
        <geom type="cylinder" size="0.04 0.02" rgba="0.3 0.3 0.8 1"/>
        <body name="left_Link2" pos="0 0 0.04287" quat="0.5 0.5 -0.5 0.5">
          <inertial pos="0.15 0 0" mass="0.22" diaginertia="0.00023 0.00014 0.00013"/>
          <joint name="left_Joint2" axis="0 0 1" range="-1.57 1.57" damping="0.01"/>
          <geom type="capsule" size="0.025" fromto="0 0 0 0.22367 0 0" rgba="0.3 0.3 0.8 1"/>
          <body name="left_Link3" pos="0.22367 -0.022592 0" quat="0.383 0 0 -0.924">
            <inertial pos="0.056 0 0" mass="0.085" diaginertia="8.1e-05 7.6e-05 2.8e-05"/>
            <joint name="left_Joint3" axis="0 0 1" range="-0.5 2.36" damping="0.01"/>
            <geom type="capsule" size="0.02" fromto="0 0 0 0.0986 0 0" rgba="0.3 0.3 0.8 1"/>
            <body name="left_Link4" pos="0.0986 -0.00211 0.0002" quat="0.5 -0.5 0.5 -0.5">
              <inertial pos="0 0 0.066" mass="0.065" diaginertia="7e-05 6.9e-05 1.7e-05"/>
              <joint name="left_Joint4" axis="0 0 -1" range="-3.14 3.14" damping="0.01"/>
              <geom type="cylinder" size="0.018 0.06" rgba="0.3 0.3 0.8 1" pos="0 0 0.06"/>
              <body name="left_Link5" pos="0 0.00015 0.12275" quat="0.707 0.707 0 0">
                <inertial pos="-0.011 0.031 0" mass="0.046" diaginertia="2.5e-05 1.8e-05 1.6e-05"/>
                <joint name="left_Joint5" axis="0 0 1" range="-1.57 1.5" damping="0.01"/>
                <geom type="capsule" size="0.015" fromto="0 0 0 0 0.0573 0" rgba="0.3 0.3 0.8 1"/>
                <body name="left_Link6" pos="-0.00385 0.0573 -0.00035" quat="0.707 -0.707 0 0">
                  <inertial pos="-0.032 0 0.027" mass="0.12" diaginertia="9.1e-05 7.9e-05 3.5e-05"/>
                  <joint name="left_Joint6" axis="0 0 -1" range="-3.14 3.14" damping="0.01"/>
                  <geom type="box" size="0.03 0.025 0.06" rgba="0.3 0.3 0.8 1" pos="0 0 0.065"/>
                  <!-- 夹爪底座 -->
                  <geom type="box" size="0.015 0.015 0.015" rgba="0.3 0.3 0.8 1" pos="0 0 0.13"/>
                  <!-- 末端执行器参考点 -->
                  <geom size="0.008" rgba="0 1 0 1" pos="0 0 0.13118"/>
                  <body name="left_Link7" pos="-0.0002 0.050502 0.13118" quat="0.707 -0.707 0 0">
                    <inertial pos="0 0.043 0.011" mass="0.026" diaginertia="8.5e-06 6.5e-06 4.7e-06"/>
                    <joint name="left_finger" type="slide" axis="0 0 1" range="-0.05 0" damping="0.005"/>
                    <geom type="box" size="0.008 0.01 0.025" rgba="0.5 0.5 0.5 1" pos="0 0 0.025"/>
                  </body>
                  <body name="left_Link8" pos="-0.0002 -0.050498 0.13118" quat="0.707 0.707 0 0">
                    <inertial pos="0 -0.043 0.011" mass="0.026" diaginertia="8.5e-06 6.5e-06 4.7e-06"/>
                    <joint name="left_right_finger" type="slide" axis="0 0 -1" range="0 0.05" damping="0.005"/>
                    <geom type="box" size="0.008 0.01 0.025" rgba="0.5 0.5 0.5 1" pos="0 0 0.025"/>
                  </body>
                </body>
              </body>
            </body>
          </body>
        </body>
      </body>
    </body>

    <!-- 右臂 (红色) -->
    <body name="right_base_link" pos="0.35 0 0">
      <geom type="cylinder" size="0.05 0.03" rgba="0.8 0.3 0.3 1" pos="0 0 0.065"/>
      <body name="right_Link1" pos="0 0 0.1295">
        <inertial pos="0 0 0.003" mass="0.19" diaginertia="0.00034 0.00026 0.00015"/>
        <joint name="right_Joint1" axis="0 0 1" range="-2.16 2.16" damping="0.01"/>
        <geom type="cylinder" size="0.04 0.02" rgba="0.8 0.3 0.3 1"/>
        <body name="right_Link2" pos="0 0 0.04287" quat="0.5 0.5 -0.5 0.5">
          <inertial pos="0.15 0 0" mass="0.22" diaginertia="0.00023 0.00014 0.00013"/>
          <joint name="right_Joint2" axis="0 0 1" range="-1.57 1.57" damping="0.01"/>
          <geom type="capsule" size="0.025" fromto="0 0 0 0.22367 0 0" rgba="0.8 0.3 0.3 1"/>
          <body name="right_Link3" pos="0.22367 -0.022592 0" quat="0.383 0 0 -0.924">
            <inertial pos="0.056 0 0" mass="0.085" diaginertia="8.1e-05 7.6e-05 2.8e-05"/>
            <joint name="right_Joint3" axis="0 0 1" range="-0.5 2.36" damping="0.01"/>
            <geom type="capsule" size="0.02" fromto="0 0 0 0.0986 0 0" rgba="0.8 0.3 0.3 1"/>
            <body name="right_Link4" pos="0.0986 -0.00211 0.0002" quat="0.5 -0.5 0.5 -0.5">
              <inertial pos="0 0 0.066" mass="0.065" diaginertia="7e-05 6.9e-05 1.7e-05"/>
              <joint name="right_Joint4" axis="0 0 -1" range="-3.14 3.14" damping="0.01"/>
              <geom type="cylinder" size="0.018 0.06" rgba="0.8 0.3 0.3 1" pos="0 0 0.06"/>
              <body name="right_Link5" pos="0 0.00015 0.12275" quat="0.707 0.707 0 0">
                <inertial pos="-0.011 0.031 0" mass="0.046" diaginertia="2.5e-05 1.8e-05 1.6e-05"/>
                <joint name="right_Joint5" axis="0 0 1" range="-1.57 1.5" damping="0.01"/>
                <geom type="capsule" size="0.015" fromto="0 0 0 0 0.0573 0" rgba="0.8 0.3 0.3 1"/>
                <body name="right_Link6" pos="-0.00385 0.0573 -0.00035" quat="0.707 -0.707 0 0">
                  <inertial pos="-0.032 0 0.027" mass="0.12" diaginertia="9.1e-05 7.9e-05 3.5e-05"/>
                  <joint name="right_Joint6" axis="0 0 -1" range="-3.14 3.14" damping="0.01"/>
                  <geom type="box" size="0.03 0.025 0.06" rgba="0.8 0.3 0.3 1" pos="0 0 0.065"/>
                  <!-- 夹爪底座 -->
                  <geom type="box" size="0.015 0.015 0.015" rgba="0.8 0.3 0.3 1" pos="0 0 0.13"/>
                  <!-- 末端执行器参考点 -->
                  <geom size="0.008" rgba="0 1 0 1" pos="0 0 0.13118"/>
                  <body name="right_Link7" pos="-0.0002 0.050502 0.13118" quat="0.707 -0.707 0 0">
                    <inertial pos="0 0.043 0.011" mass="0.026" diaginertia="8.5e-06 6.5e-06 4.7e-06"/>
                    <joint name="right_left_finger" type="slide" axis="0 0 1" range="-0.05 0" damping="0.005"/>
                    <geom type="box" size="0.008 0.01 0.025" rgba="0.5 0.5 0.5 1" pos="0 0 0.025"/>
                  </body>
                  <body name="right_Link8" pos="-0.0002 -0.050498 0.13118" quat="0.707 0.707 0 0">
                    <inertial pos="0 -0.043 0.011" mass="0.026" diaginertia="8.5e-06 6.5e-06 4.7e-06"/>
                    <joint name="right_right_finger" type="slide" axis="0 0 -1" range="0 0.05" damping="0.005"/>
                    <geom type="box" size="0.008 0.01 0.025" rgba="0.5 0.5 0.5 1" pos="0 0 0.025"/>
                  </body>
                </body>
              </body>
            </body>
          </body>
        </body>
      </body>
    </body>
  </worldbody>

  <actuator>
    <!-- 左臂执行器 -->
    <motor joint="left_Joint1" gear="100"/>
    <motor joint="left_Joint2" gear="100"/>
    <motor joint="left_Joint3" gear="100"/>
    <motor joint="left_Joint4" gear="100"/>
    <motor joint="left_Joint5" gear="100"/>
    <motor joint="left_Joint6" gear="100"/>
    <position joint="left_finger" kp="10"/>
    <position joint="left_right_finger" kp="10"/>

    <!-- 右臂执行器 -->
    <motor joint="right_Joint1" gear="100"/>
    <motor joint="right_Joint2" gear="100"/>
    <motor joint="right_Joint3" gear="100"/>
    <motor joint="right_Joint4" gear="100"/>
    <motor joint="right_Joint5" gear="100"/>
    <motor joint="right_Joint6" gear="100"/>
    <position joint="right_left_finger" kp="10"/>
    <position joint="right_right_finger" kp="10"/>
  </actuator>

  <contact>
    <!-- 左臂自碰撞排除 -->
    <exclude body1="left_base_link" body2="left_Link1"/>
    <exclude body1="left_Link1" body2="left_Link2"/>
    <exclude body1="left_Link2" body2="left_Link3"/>
    <exclude body1="left_Link3" body2="left_Link4"/>
    <exclude body1="left_Link4" body2="left_Link5"/>
    <exclude body1="left_Link5" body2="left_Link6"/>
    <exclude body1="left_Link6" body2="left_Link7"/>
    <exclude body1="left_Link6" body2="left_Link8"/>

    <!-- 右臂自碰撞排除 -->
    <exclude body1="right_base_link" body2="right_Link1"/>
    <exclude body1="right_Link1" body2="right_Link2"/>
    <exclude body1="right_Link2" body2="right_Link3"/>
    <exclude body1="right_Link3" body2="right_Link4"/>
    <exclude body1="right_Link4" body2="right_Link5"/>
    <exclude body1="right_Link5" body2="right_Link6"/>
    <exclude body1="right_Link6" body2="right_Link7"/>
    <exclude body1="right_Link6" body2="right_Link8"/>
  </contact>
</mujoco>
