<?xml version="1.0"?>
<robot name="Alicia-D">
  <!-- Base Link -->
  <link name="base_link">
    <visual>
      <origin xyz="0 0 0" rpy="0 0 0"/>
      <geometry>
        <mesh filename="../../meshes/Alicia-D_v5_4/base_link.STL"/>
      </geometry>
      <material name="">
        <color rgba="0.79216 0.81961 0.93333 1"/>
      </material>
    </visual>
    <collision>
      <origin xyz="0 0 0" rpy="0 0 0"/>
      <geometry>
        <mesh filename="../../meshes/Alicia-D_v5_4/base_link.STL"/>
      </geometry>
    </collision>
    <inertial>
      <origin xyz="0.0088384 -4.0592E-06 0.020618" rpy="0 0 0"/>
      <mass value="0.35693"/>
      <inertia
        ixx="0.00047805"
        ixy="-1.134E-08"
        ixz="5.1005E-05"
        iyy="0.00051481"
        iyz="-2.3755E-08"
        izz="0.00031508"/>
    </inertial>
  </link>

  <!-- Joint 1 -->
  <joint name="Joint1" type="revolute">
    <origin xyz="0 0 0.06115" rpy="0 0 0"/>
    <parent link="base_link"/>
    <child link="Link1"/>
    <axis xyz="0 0 1"/>
    <limit lower="-3.14159" upper="3.14159" effort="10" velocity="3.14159"/>
  </joint>

  <link name="Link1">
    <visual>
      <origin xyz="0 0 0" rpy="0 0 0"/>
      <geometry>
        <mesh filename="../../meshes/Alicia-D_v5_4/Link1.STL"/>
      </geometry>
      <material name="">
        <color rgba="0.79216 0.81961 0.93333 1"/>
      </material>
    </visual>
    <collision>
      <origin xyz="0 0 0" rpy="0 0 0"/>
      <geometry>
        <mesh filename="../../meshes/Alicia-D_v5_4/Link1.STL"/>
      </geometry>
    </collision>
    <inertial>
      <origin xyz="5.3476E-05 -0.00081566 0.046695" rpy="0 0 0"/>
      <mass value="0.13086"/>
      <inertia
        ixx="0.00012312"
        ixy="-8.1912E-08"
        ixz="-5.5682E-07"
        iyy="0.00011659"
        iyz="5.8342E-06"
        izz="5.0653E-05"/>
    </inertial>
  </link>

  <!-- Joint 2 -->
  <joint name="Joint2" type="revolute">
    <origin xyz="0 0 0.0645" rpy="1.5708 0 0"/>
    <parent link="Link1"/>
    <child link="Link2"/>
    <axis xyz="0 0 1"/>
    <limit lower="-1.91986" upper="1.91986" effort="10" velocity="3.14159"/>
  </joint>

  <link name="Link2">
    <visual>
      <origin xyz="0 0 0" rpy="0 0 0"/>
      <geometry>
        <mesh filename="../../meshes/Alicia-D_v5_4/Link2.STL"/>
      </geometry>
      <material name="">
        <color rgba="0.79216 0.81961 0.93333 1"/>
      </material>
    </visual>
    <collision>
      <origin xyz="0 0 0" rpy="0 0 0"/>
      <geometry>
        <mesh filename="../../meshes/Alicia-D_v5_4/Link2.STL"/>
      </geometry>
    </collision>
    <inertial>
      <origin xyz="3.0783E-05 0.0035616 0.061605" rpy="0 0 0"/>
      <mass value="0.12033"/>
      <inertia
        ixx="9.5938E-05"
        ixy="-1.5598E-08"
        ixz="3.1966E-07"
        iyy="8.9398E-05"
        iyz="-4.4056E-06"
        izz="3.5966E-05"/>
    </inertial>
  </link>

  <!-- Joint 3 -->
  <joint name="Joint3" type="revolute">
    <origin xyz="0 0 0.09685" rpy="0 0 0"/>
    <parent link="Link2"/>
    <child link="Link3"/>
    <axis xyz="0 0 1"/>
    <limit lower="-1.91986" upper="1.91986" effort="10" velocity="3.14159"/>
  </joint>

  <link name="Link3">
    <visual>
      <origin xyz="0 0 0" rpy="0 0 0"/>
      <geometry>
        <mesh filename="../../meshes/Alicia-D_v5_4/Link3.STL"/>
      </geometry>
      <material name="">
        <color rgba="0.79216 0.81961 0.93333 1"/>
      </material>
    </visual>
    <collision>
      <origin xyz="0 0 0" rpy="0 0 0"/>
      <geometry>
        <mesh filename="../../meshes/Alicia-D_v5_4/Link3.STL"/>
      </geometry>
    </collision>
    <inertial>
      <origin xyz="-1.8013E-05 0.012327 0.019935" rpy="0 0 0"/>
      <mass value="0.049542"/>
      <inertia
        ixx="2.213E-05"
        ixy="2.1881E-08"
        ixz="-1.7208E-08"
        iyy="2.1006E-05"
        iyz="-3.6651E-06"
        izz="1.1858E-05"/>
    </inertial>
  </link>

  <!-- Joint 4 -->
  <joint name="Joint4" type="revolute">
    <origin xyz="0 0.0285 0.02435" rpy="-1.5708 0 0"/>
    <parent link="Link3"/>
    <child link="Link4"/>
    <axis xyz="0 0 1"/>
    <limit lower="-3.14159" upper="3.14159" effort="10" velocity="3.14159"/>
  </joint>

  <link name="Link4">
    <visual>
      <origin xyz="0 0 0" rpy="0 0 0"/>
      <geometry>
        <mesh filename="../../meshes/Alicia-D_v5_4/Link4.STL"/>
      </geometry>
      <material name="">
        <color rgba="0.79216 0.81961 0.93333 1"/>
      </material>
    </visual>
    <collision>
      <origin xyz="0 0 0" rpy="0 0 0"/>
      <geometry>
        <mesh filename="../../meshes/Alicia-D_v5_4/Link4.STL"/>
      </geometry>
    </collision>
    <inertial>
      <origin xyz="-4.4184E-06 -0.00020255 0.046155" rpy="0 0 0"/>
      <mass value="0.074312"/>
      <inertia
        ixx="4.8601E-05"
        ixy="3.4009E-09"
        ixz="7.6081E-09"
        iyy="4.7773E-05"
        iyz="1.2063E-06"
        izz="1.2467E-05"/>
    </inertial>
  </link>

  <!-- Joint 5 -->
  <joint name="Joint5" type="revolute">
    <origin xyz="0 0 0.0685" rpy="1.5708 0 0"/>
    <parent link="Link4"/>
    <child link="Link5"/>
    <axis xyz="0 0 1"/>
    <limit lower="-1.8326" upper="1.8326" effort="10" velocity="3.14159"/>
  </joint>

  <link name="Link5">
    <visual>
      <origin xyz="0 0 0" rpy="0 0 0"/>
      <geometry>
        <mesh filename="../../meshes/Alicia-D_v5_4/Link5.STL"/>
      </geometry>
      <material name="">
        <color rgba="0.79216 0.81961 0.93333 1"/>
      </material>
    </visual>
    <collision>
      <origin xyz="0 0 0" rpy="0 0 0"/>
      <geometry>
        <mesh filename="../../meshes/Alicia-D_v5_4/Link5.STL"/>
      </geometry>
    </collision>
    <inertial>
      <origin xyz="1.6625E-06 0.0097886 0.016831" rpy="0 0 0"/>
      <mass value="0.038765"/>
      <inertia
        ixx="1.1451E-05"
        ixy="-3.1434E-10"
        ixz="-1.5654E-09"
        iyy="1.0743E-05"
        iyz="-2.3071E-06"
        izz="5.9913E-06"/>
    </inertial>
  </link>

  <!-- Joint 6 -->
  <joint name="Joint6" type="revolute">
    <origin xyz="0 0.02115 0.02115" rpy="-1.5708 0 0"/>
    <parent link="Link5"/>
    <child link="Link6"/>
    <axis xyz="0 0 1"/>
    <limit lower="-3.14159" upper="3.14159" effort="10" velocity="3.14159"/>
  </joint>

  <link name="Link6">
    <visual>
      <origin xyz="0 0 0" rpy="0 0 0"/>
      <geometry>
        <mesh filename="../../meshes/Alicia-D_v5_4/Link6.STL"/>
      </geometry>
      <material name="">
        <color rgba="0.79216 0.81961 0.93333 1"/>
      </material>
    </visual>
    <collision>
      <origin xyz="0 0 0" rpy="0 0 0"/>
      <geometry>
        <mesh filename="../../meshes/Alicia-D_v5_4/Link6.STL"/>
      </geometry>
    </collision>
    <inertial>
      <origin xyz="-9.0615E-07 6.9424E-05 0.0092407" rpy="0 0 0"/>
      <mass value="0.018578"/>
      <inertia
        ixx="2.8885E-06"
        ixy="1.8926E-10"
        ixz="3.0864E-10"
        iyy="2.7889E-06"
        iyz="-1.9201E-07"
        izz="2.6735E-06"/>
    </inertial>
  </link>

  <!-- Gripper Base -->
  <joint name="gripper_base_joint" type="fixed">
    <origin xyz="0 0 0.01585" rpy="0 0 0"/>
    <parent link="Link6"/>
    <child link="gripper_base_link"/>
  </joint>

  <link name="gripper_base_link">
    <visual>
      <origin xyz="0 0 0" rpy="0 0 0"/>
      <geometry>
        <mesh filename="../../meshes/Alicia-D_v5_4/gripper_base_link_50mm.STL"/>
      </geometry>
      <material name="">
        <color rgba="0.79216 0.81961 0.93333 1"/>
      </material>
    </visual>
    <collision>
      <origin xyz="0 0 0" rpy="0 0 0"/>
      <geometry>
        <mesh filename="../../meshes/Alicia-D_v5_4/gripper_base_link_50mm.STL"/>
      </geometry>
    </collision>
    <inertial>
      <origin xyz="-6.1629E-17 -1.3878E-17 0.02655" rpy="0 0 0"/>
      <mass value="0.03339"/>
      <inertia
        ixx="1.6916E-05"
        ixy="-6.505E-22"
        ixz="-7.806E-22"
        iyy="1.6916E-05"
        iyz="6.505E-23"
        izz="2.5041E-06"/>
    </inertial>
  </link>

  <!-- Left Finger -->
  <joint name="left_finger" type="prismatic">
    <origin xyz="0 -0.0085 0.0481" rpy="0 0 0"/>
    <parent link="gripper_base_link"/>
    <child link="left_gripper"/>
    <axis xyz="0 1 0"/>
    <limit lower="0" upper="0.025" effort="10" velocity="0.1"/>
  </joint>

  <link name="left_gripper">
    <visual>
      <origin xyz="0 0 0" rpy="0 0 0"/>
      <geometry>
        <mesh filename="../../meshes/Alicia-D_v5_4/left_gripper.STL"/>
      </geometry>
      <material name="">
        <color rgba="0.79216 0.81961 0.93333 1"/>
      </material>
    </visual>
    <collision>
      <origin xyz="0 0 0" rpy="0 0 0"/>
      <geometry>
        <mesh filename="../../meshes/Alicia-D_v5_4/left_gripper.STL"/>
      </geometry>
    </collision>
    <inertial>
      <origin xyz="-2.7756E-17 0.0050943 0.0057047" rpy="0 0 0"/>
      <mass value="0.0040827"/>
      <inertia
        ixx="1.0207E-06"
        ixy="0"
        ixz="0"
        iyy="7.5803E-07"
        iyz="-1.8698E-07"
        izz="5.4413E-07"/>
    </inertial>
  </link>

  <!-- Right Finger -->
  <joint name="right_finger" type="prismatic">
    <origin xyz="0 0.0085 0.0481" rpy="0 0 0"/>
    <parent link="gripper_base_link"/>
    <child link="right_gripper"/>
    <axis xyz="0 1 0"/>
    <limit lower="-0.025" upper="0" effort="10" velocity="0.1"/>
  </joint>

  <link name="right_gripper">
    <visual>
      <origin xyz="0 0 0" rpy="0 0 0"/>
      <geometry>
        <mesh filename="../../meshes/Alicia-D_v5_4/right_gripper.STL"/>
      </geometry>
      <material name="">
        <color rgba="0.79216 0.81961 0.93333 1"/>
      </material>
    </visual>
    <collision>
      <origin xyz="0 0 0" rpy="0 0 0"/>
      <geometry>
        <mesh filename="../../meshes/Alicia-D_v5_4/right_gripper.STL"/>
      </geometry>
    </collision>
    <inertial>
      <origin xyz="0 -0.0050943 0.0057047" rpy="0 0 0"/>
      <mass value="0.0040827"/>
      <inertia
        ixx="1.0207E-06"
        ixy="0"
        ixz="0"
        iyy="7.5803E-07"
        iyz="1.8698E-07"
        izz="5.4413E-07"/>
    </inertial>
  </link>

  <!-- Tool0 (End Effector Frame) -->
  <joint name="gripper_tool0_joint" type="fixed">
    <origin xyz="0 0 0.06535" rpy="0 0 0"/>
    <parent link="gripper_base_link"/>
    <child link="tool0"/>
  </joint>

  <link name="tool0"/>

</robot>
